Running script...
Traceback (most recent call last):
  File "Classifier_experimentOne_isUsable/Classifier_test.py", line 250, in <module>
    CV=classifier_validation(Bc_path=BC, feture_path=F, speck_path=S, logfile_path="ClassifierTestLogs",max_files=50)
TypeError: __init__() got an unexpected keyword argument 'max_files'
